I'm sorry, but an uncaught exception occurred.

While running game code:
  File "game/script.rpy", line 203, in script call
    call show_trust
  File "game/script.rpy", line 203, in script call
    call show_trust
ScriptError: could not find label 'show_trust'.

-- Full Traceback ------------------------------------------------------------

Full traceback:
  File "game/script.rpy", line 203, in script call
    call show_trust
  File "C:\Users\joann\Downloads\renpy-8.0.3-sdk\renpy\ast.py", line 1705, in execute
    rv = renpy.game.context().call(label, return_site=self.next.name)
  File "game/script.rpy", line 203, in script call
    call show_trust
  File "C:\Users\joann\Downloads\renpy-8.0.3-sdk\renpy\script.py", line 927, in lookup
    raise ScriptError("could not find label '%s'." % str(original))
ScriptError: could not find label 'show_trust'.

Windows-10-10.0.22000 AMD64
Ren'Py 8.0.3.22090809
BetaGame 1.0
Wed Sep 28 16:01:55 2022
