I'm sorry, but an uncaught exception occurred.

While running game code:
  File "game/script.rpy", line 336, in script
    call screen conflict_success
  File "renpy/common/000statements.rpy", line 609, in execute_call_screen
    store._return = renpy.call_screen(name, *args, **kwargs)
Exception: Screen conflict_success is not known.


-- Full Traceback ------------------------------------------------------------

Full traceback:
  File "game/script.rpy", line 336, in script
    call screen conflict_success
  File "C:\Users\joann\Downloads\renpy-8.0.3-sdk\renpy\ast.py", line 2232, in execute
    self.call("execute")
  File "C:\Users\joann\Downloads\renpy-8.0.3-sdk\renpy\ast.py", line 2220, in call
    return renpy.statements.call(method, parsed, *args, **kwargs)
  File "C:\Users\joann\Downloads\renpy-8.0.3-sdk\renpy\statements.py", line 281, in call
    return method(parsed, *args, **kwargs)
  File "renpy/common/000statements.rpy", line 609, in execute_call_screen
    store._return = renpy.call_screen(name, *args, **kwargs)
  File "C:\Users\joann\Downloads\renpy-8.0.3-sdk\renpy\exports.py", line 3167, in call_screen
    show_screen(_screen_name, _transient=True, *args, **kwargs)
  File "C:\Users\joann\Downloads\renpy-8.0.3-sdk\renpy\display\screen.py", line 1185, in show_screen
    raise Exception("Screen %s is not known.\n" % (name[0],))
Exception: Screen conflict_success is not known.


Windows-10-10.0.22000 AMD64
Ren'Py 8.0.3.22090809
BetaGame 1.0
Fri Sep 30 00:01:19 2022
