I'm sorry, but an uncaught exception occurred.

While parsing /Users/fanyupei/Downloads/y2s1/ntu EDge/github/TTSH-OB/game/chapter_1_script/scene_2.rpy.
Exception: Line with id start_7914e3bd appeared twice, at game/chapter_1_script/scene_2.rpy:12 and game/script.rpy:12.

-- Full Traceback ------------------------------------------------------------

Full traceback:
  File "/Volumes/renpy-7.5.3-sdk/renpy-7.5.3-sdk/renpy/bootstrap.py", line 277, in bootstrap
    renpy.main.main()
  File "/Volumes/renpy-7.5.3-sdk/renpy-7.5.3-sdk/renpy/main.py", line 490, in main
    renpy.game.script.load_script() # sets renpy.game.script.
  File "/Volumes/renpy-7.5.3-sdk/renpy-7.5.3-sdk/renpy/script.py", line 297, in load_script
    self.load_appropriate_file(".rpyc", ".rpy", dir, fn, initcode)
  File "/Volumes/renpy-7.5.3-sdk/renpy-7.5.3-sdk/renpy/script.py", line 809, in load_appropriate_file
    self.finish_load(stmts, initcode, filename=lastfn) # type: ignore
  File "/Volumes/renpy-7.5.3-sdk/renpy-7.5.3-sdk/renpy/script.py", line 427, in finish_load
    self.translator.take_translates(all_stmts)
  File "/Volumes/renpy-7.5.3-sdk/renpy-7.5.3-sdk/renpy/translation/__init__.py", line 169, in take_translates
    n.filename, n.linenumber))
Exception: Line with id start_7914e3bd appeared twice, at game/chapter_1_script/scene_2.rpy:12 and game/script.rpy:12.

Darwin-21.6.0-x86_64-i386-64bit x86_64
Ren'Py 7.5.3.22090809
BetaGame 1.0
Mon Oct 10 11:26:24 2022
